Workbook

Sheet Reporting Hebdo
D1: Reporting Cash Hebdomadaire – Centralisation Côte d'Ivoire
C2: Soldes bancaires au | E2: 46295 | M2: Semaine | N2: S1 | P2: S2 | R2: S3 | T2: S4 | V2: S5
C3: Taux FCFA / € | E3: 655.957 | M3: Du | N3: 46300 | P3: =N3+7 | R3: =P3+7 | T3: =R3+7 | V3: =T3+7
C4: Édité le | E4: 46302 | M4: Au | N4: =N3+6 | P4: =P3+6 | R4: =R3+6 | T4: =T3+6 | V4: =V3+6
C6: Soldes Bancaires (Réel) – Comptes de sociétés
F8: En euros | G8: S1 | H8: S2 | I8: S3 | J8: S4 | K8: S5 | M8: En FCFA | N8: S1 | P8: S2 | R8: S3 | T8: S4 | V8: S5
F9: =$E$2 | G9: =N4 | H9: =P4 | I9: =R4 | J9: =T4 | K9: =V4 | M9: =$E$2 | N9: =N3 | O9: =N4 | P9: =P3 | Q9: =P4 | R9: =R3 | S9: =R4 | T9: =T3 | U9: =T4 | V9: =V3 | W9: =V4 | Y9: COMMENTAIRES
C10: BANQUE | D10: Destination (position CI) | F10: Solde réel | G10: Solde théorique | H10: Solde théorique | I10: Solde théorique | J10: Solde théorique | K10: Solde théorique | M10: Solde réel | N10: Prévisions (flux) | O10: Solde théorique | P10: Prévisions (flux) | Q10: Solde théorique | R10: Prévisions (flux) | S10: Solde théorique | T10: Prévisions (flux) | U10: Solde théorique | V10: Prévisions (flux) | W10: Solde théorique
A11: PICI | C11: PROMOTION (PICI) | F11: =M11/$E$3 | G11: =O11/$E$3 | H11: =Q11/$E$3 | I11: =S11/$E$3 | J11: =U11/$E$3 | K11: =W11/$E$3 | M11: =SUM(M12:M14) | N11: =SUMIFS('Détail fonctionnement'!$J$5:$J$505,'Détail fonctionnement'!$A$5:$A$505,N$2,'Détail fonctionnement'!$G$5:$G$505,"O",'Détail fonctionnement'!$B$5:$B$505,$A11) | O11: =M11+N11 | P11: =SUMIFS('Détail fonctionnement'!$J$5:$J$505,'Détail fonctionnement'!$A$5:$A$505,P$2,'Détail fonctionnement'!$G$5:$G$505,"O",'Détail fonctionnement'!$B$5:$B$505,$A11) | Q11: =O11+P11 | R11: =SUMIFS('Détail fonctionnement'!$J$5:$J$505,'Détail fonctionnement'!$A$5:$A$505,R$2,'Détail fonctionnement'!$G$5:$G$505,"O",'Détail fonctionnement'!$B$5:$B$505,$A11) | S11: =Q11+R11 | T11: =SUMIFS('Détail fonctionnement'!$J$5:$J$505,'Détail fonctionnement'!$A$5:$A$505,T$2,'Détail fonctionnement'!$G$5:$G$505,"O",'Détail fonctionnement'!$B$5:$B$505,$A11) | U11: =S11+T11 | V11: =SUMIFS('Détail fonctionnement'!$J$5:$J$505,'Détail fonctionnement'!$A$5:$A$505,V$2,'Détail fonctionnement'!$G$5:$G$505,"O",'Détail fonctionnement'!$B$5:$B$505,$A11) | W11: =U11+V11
C12: SOCIETE GENERALE-PICI | D12: Dédié besoin de fonctionnement et "Netting" autres compagnies CIV | F12: =M12/$E$3 | M12: ='Position CI 30-09'!F5
C13: STANBIC-PICI | D13: Dédié besoin de fonctionnement | F13: =M13/$E$3 | M13: ='Position CI 30-09'!F6
C14: ECOBANK-PICI | D14: Dédié besoin de fonctionnement | F14: =M14/$E$3 | M14: ='Position CI 30-09'!F7
A15: FIRST | C15: PROPERTY (SCI FIRST) | F15: =M15/$E$3 | G15: =O15/$E$3 | H15: =Q15/$E$3 | I15: =S15/$E$3 | J15: =U15/$E$3 | K15: =W15/$E$3 | M15: =SUM(M16:M17) | N15: =SUMIFS('Détail fonctionnement'!$J$5:$J$505,'Détail fonctionnement'!$A$5:$A$505,N$2,'Détail fonctionnement'!$G$5:$G$505,"O",'Détail fonctionnement'!$B$5:$B$505,$A15) | O15: =M15+N15 | P15: =SUMIFS('Détail fonctionnement'!$J$5:$J$505,'Détail fonctionnement'!$A$5:$A$505,P$2,'Détail fonctionnement'!$G$5:$G$505,"O",'Détail fonctionnement'!$B$5:$B$505,$A15) | Q15: =O15+P15 | R15: =SUMIFS('Détail fonctionnement'!$J$5:$J$505,'Détail fonctionnement'!$A$5:$A$505,R$2,'Détail fonctionnement'!$G$5:$G$505,"O",'Détail fonctionnement'!$B$5:$B$505,$A15) | S15: =Q15+R15 | T15: =SUMIFS('Détail fonctionnement'!$J$5:$J$505,'Détail fonctionnement'!$A$5:$A$505,T$2,'Détail fonctionnement'!$G$5:$G$505,"O",'Détail fonctionnement'!$B$5:$B$505,$A15) | U15: =S15+T15 | V15: =SUMIFS('Détail fonctionnement'!$J$5:$J$505,'Détail fonctionnement'!$A$5:$A$505,V$2,'Détail fonctionnement'!$G$5:$G$505,"O",'Détail fonctionnement'!$B$5:$B$505,$A15) | W15: =U15+V15
C16: SOCIETE GENERALE-FIRST | D16: Dédié besoin de fonctionnement | F16: =M16/$E$3 | M16: ='Position CI 30-09'!F8
C17: STANBIC-FIRST | D17: Dédié besoin de fonctionnement | F17: =M17/$E$3 | M17: ='Position CI 30-09'!F9
A18: TERASSON | C18: TERASSON | F18: =M18/$E$3 | G18: =O18/$E$3 | H18: =Q18/$E$3 | I18: =S18/$E$3 | J18: =U18/$E$3 | K18: =W18/$E$3 | M18: =SUM(M19:M20) | N18: =SUMIFS('Détail fonctionnement'!$J$5:$J$505,'Détail fonctionnement'!$A$5:$A$505,N$2,'Détail fonctionnement'!$G$5:$G$505,"O",'Détail fonctionnement'!$B$5:$B$505,$A18) | O18: =M18+N18 | P18: =SUMIFS('Détail fonctionnement'!$J$5:$J$505,'Détail fonctionnement'!$A$5:$A$505,P$2,'Détail fonctionnement'!$G$5:$G$505,"O",'Détail fonctionnement'!$B$5:$B$505,$A18) | Q18: =O18+P18 | R18: =SUMIFS('Détail fonctionnement'!$J$5:$J$505,'Détail fonctionnement'!$A$5:$A$505,R$2,'Détail fonctionnement'!$G$5:$G$505,"O",'Détail fonctionnement'!$B$5:$B$505,$A18) | S18: =Q18+R18 | T18: =SUMIFS('Détail fonctionnement'!$J$5:$J$505,'Détail fonctionnement'!$A$5:$A$505,T$2,'Détail fonctionnement'!$G$5:$G$505,"O",'Détail fonctionnement'!$B$5:$B$505,$A18) | U18: =S18+T18 | V18: =SUMIFS('Détail fonctionnement'!$J$5:$J$505,'Détail fonctionnement'!$A$5:$A$505,V$2,'Détail fonctionnement'!$G$5:$G$505,"O",'Détail fonctionnement'!$B$5:$B$505,$A18) | W18: =U18+V18
C19: SOCIETE GENERALE-TERASSON | D19: Dédié besoin de fonctionnement | F19: =M19/$E$3 | M19: ='Position CI 30-09'!F10
C20: ECOBANK -TERASSON | D20: Dédié besoin de fonctionnement | F20: =M20/$E$3 | M20: ='Position CI 30-09'!F11
A21: RIVIERA | C21: RIVIERA PARK | F21: =M21/$E$3 | G21: =O21/$E$3 | H21: =Q21/$E$3 | I21: =S21/$E$3 | J21: =U21/$E$3 | K21: =W21/$E$3 | M21: =SUM(M22:M22) | N21: =SUMIFS('Détail fonctionnement'!$J$5:$J$505,'Détail fonctionnement'!$A$5:$A$505,N$2,'Détail fonctionnement'!$G$5:$G$505,"O",'Détail fonctionnement'!$B$5:$B$505,$A21) | O21: =M21+N21 | P21: =SUMIFS('Détail fonctionnement'!$J$5:$J$505,'Détail fonctionnement'!$A$5:$A$505,P$2,'Détail fonctionnement'!$G$5:$G$505,"O",'Détail fonctionnement'!$B$5:$B$505,$A21) | Q21: =O21+P21 | R21: =SUMIFS('Détail fonctionnement'!$J$5:$J$505,'Détail fonctionnement'!$A$5:$A$505,R$2,'Détail fonctionnement'!$G$5:$G$505,"O",'Détail fonctionnement'!$B$5:$B$505,$A21) | S21: =Q21+R21 | T21: =SUMIFS('Détail fonctionnement'!$J$5:$J$505,'Détail fonctionnement'!$A$5:$A$505,T$2,'Détail fonctionnement'!$G$5:$G$505,"O",'Détail fonctionnement'!$B$5:$B$505,$A21) | U21: =S21+T21 | V21: =SUMIFS('Détail fonctionnement'!$J$5:$J$505,'Détail fonctionnement'!$A$5:$A$505,V$2,'Détail fonctionnement'!$G$5:$G$505,"O",'Détail fonctionnement'!$B$5:$B$505,$A21) | W21: =U21+V21
C22: SOCIETE GENERALE-RIVIERA | D22: Dédié besoin de fonctionnement | F22: =M22/$E$3 | M22: ='Position CI 30-09'!F12
A23: SCO AO | C23: SCO AO | F23: =M23/$E$3 | G23: =O23/$E$3 | H23: =Q23/$E$3 | I23: =S23/$E$3 | J23: =U23/$E$3 | K23: =W23/$E$3 | M23: =SUM(M24:M28) | N23: =SUMIFS('Détail fonctionnement'!$J$5:$J$505,'Détail fonctionnement'!$A$5:$A$505,N$2,'Détail fonctionnement'!$G$5:$G$505,"O",'Détail fonctionnement'!$B$5:$B$505,$A23) | O23: =M23+N23 | P23: =SUMIFS('Détail fonctionnement'!$J$5:$J$505,'Détail fonctionnement'!$A$5:$A$505,P$2,'Détail fonctionnement'!$G$5:$G$505,"O",'Détail fonctionnement'!$B$5:$B$505,$A23) | Q23: =O23+P23 | R23: =SUMIFS('Détail fonctionnement'!$J$5:$J$505,'Détail fonctionnement'!$A$5:$A$505,R$2,'Détail fonctionnement'!$G$5:$G$505,"O",'Détail fonctionnement'!$B$5:$B$505,$A23) | S23: =Q23+R23 | T23: =SUMIFS('Détail fonctionnement'!$J$5:$J$505,'Détail fonctionnement'!$A$5:$A$505,T$2,'Détail fonctionnement'!$G$5:$G$505,"O",'Détail fonctionnement'!$B$5:$B$505,$A23) | U23: =S23+T23 | V23: =SUMIFS('Détail fonctionnement'!$J$5:$J$505,'Détail fonctionnement'!$A$5:$A$505,V$2,'Détail fonctionnement'!$G$5:$G$505,"O",'Détail fonctionnement'!$B$5:$B$505,$A23) | W23: =U23+V23
C24: BANK OF AFRICA-SCO AO | D24: Dédié besoin de fonctionnement | F24: =M24/$E$3 | M24: ='Position CI 30-09'!F14
C25: BACI-CompteCourant | D25: Dédié besoin de fonctionnement | F25: =M25/$E$3 | M25: ='Position CI 30-09'!F15
C26: BACI-Projet | D26: Dédié paiement Projet SCO | F26: =M26/$E$3 | M26: ='Position CI 30-09'!F16
C27: BACI-AGORA | D27: Dédié paiement Projet SCO | F27: =M27/$E$3 | M27: ='Position CI 30-09'!F17
C28: ECOBANK - SCO AO | D28: Dédié besoin de fonctionnement | F28: =M28/$E$3 | M28: ='Position CI 30-09'!F18
A29: FINAFRICA | C29: FINAFRICA CI | F29: =M29/$E$3 | G29: =O29/$E$3 | H29: =Q29/$E$3 | I29: =S29/$E$3 | J29: =U29/$E$3 | K29: =W29/$E$3 | M29: =SUM(M30:M31) | N29: =SUMIFS('Détail fonctionnement'!$J$5:$J$505,'Détail fonctionnement'!$A$5:$A$505,N$2,'Détail fonctionnement'!$G$5:$G$505,"O",'Détail fonctionnement'!$B$5:$B$505,$A29) | O29: =M29+N29 | P29: =SUMIFS('Détail fonctionnement'!$J$5:$J$505,'Détail fonctionnement'!$A$5:$A$505,P$2,'Détail fonctionnement'!$G$5:$G$505,"O",'Détail fonctionnement'!$B$5:$B$505,$A29) | Q29: =O29+P29 | R29: =SUMIFS('Détail fonctionnement'!$J$5:$J$505,'Détail fonctionnement'!$A$5:$A$505,R$2,'Détail fonctionnement'!$G$5:$G$505,"O",'Détail fonctionnement'!$B$5:$B$505,$A29) | S29: =Q29+R29 | T29: =SUMIFS('Détail fonctionnement'!$J$5:$J$505,'Détail fonctionnement'!$A$5:$A$505,T$2,'Détail fonctionnement'!$G$5:$G$505,"O",'Détail fonctionnement'!$B$5:$B$505,$A29) | U29: =S29+T29 | V29: =SUMIFS('Détail fonctionnement'!$J$5:$J$505,'Détail fonctionnement'!$A$5:$A$505,V$2,'Détail fonctionnement'!$G$5:$G$505,"O",'Détail fonctionnement'!$B$5:$B$505,$A29) | W29: =U29+V29
C30: SOCIETE GENERALE-FINAFRICA | D30: Dédié besoin de fonctionnement | F30: =M30/$E$3 | M30: ='Position CI 30-09'!F19
C31: ECOBANK-FINAFRICA | D31: Dédié besoin de fonctionnement | F31: =M31/$E$3 | M31: ='Position CI 30-09'!F20
A32: AB CENTER | C32: AB CENTER | F32: =M32/$E$3 | G32: =O32/$E$3 | H32: =Q32/$E$3 | I32: =S32/$E$3 | J32: =U32/$E$3 | K32: =W32/$E$3 | M32: =SUM(M33:M34) | N32: =SUMIFS('Détail fonctionnement'!$J$5:$J$505,'Détail fonctionnement'!$A$5:$A$505,N$2,'Détail fonctionnement'!$G$5:$G$505,"O",'Détail fonctionnement'!$B$5:$B$505,$A32) | O32: =M32+N32 | P32: =SUMIFS('Détail fonctionnement'!$J$5:$J$505,'Détail fonctionnement'!$A$5:$A$505,P$2,'Détail fonctionnement'!$G$5:$G$505,"O",'Détail fonctionnement'!$B$5:$B$505,$A32) | Q32: =O32+P32 | R32: =SUMIFS('Détail fonctionnement'!$J$5:$J$505,'Détail fonctionnement'!$A$5:$A$505,R$2,'Détail fonctionnement'!$G$5:$G$505,"O",'Détail fonctionnement'!$B$5:$B$505,$A32) | S32: =Q32+R32 | T32: =SUMIFS('Détail fonctionnement'!$J$5:$J$505,'Détail fonctionnement'!$A$5:$A$505,T$2,'Détail fonctionnement'!$G$5:$G$505,"O",'Détail fonctionnement'!$B$5:$B$505,$A32) | U32: =S32+T32 | V32: =SUMIFS('Détail fonctionnement'!$J$5:$J$505,'Détail fonctionnement'!$A$5:$A$505,V$2,'Détail fonctionnement'!$G$5:$G$505,"O",'Détail fonctionnement'!$B$5:$B$505,$A32) | W32: =U32+V32
C33: SOCIETE GENERALE-AB CENTER | D33: Dédié besoin de fonctionnement | F33: =M33/$E$3 | M33: ='Position CI 30-09'!F21
C34: ECOBANK- AB CENTER | D34: Dédié besoin de fonctionnement | F34: =M34/$E$3 | M34: ='Position CI 30-09'!F22
A35: IMMONEUF | C35: IMMONEUF | F35: =M35/$E$3 | G35: =O35/$E$3 | H35: =Q35/$E$3 | I35: =S35/$E$3 | J35: =U35/$E$3 | K35: =W35/$E$3 | M35: =SUM(M36:M38) | N35: =SUMIFS('Détail fonctionnement'!$J$5:$J$505,'Détail fonctionnement'!$A$5:$A$505,N$2,'Détail fonctionnement'!$G$5:$G$505,"O",'Détail fonctionnement'!$B$5:$B$505,$A35) | O35: =M35+N35 | P35: =SUMIFS('Détail fonctionnement'!$J$5:$J$505,'Détail fonctionnement'!$A$5:$A$505,P$2,'Détail fonctionnement'!$G$5:$G$505,"O",'Détail fonctionnement'!$B$5:$B$505,$A35) | Q35: =O35+P35 | R35: =SUMIFS('Détail fonctionnement'!$J$5:$J$505,'Détail fonctionnement'!$A$5:$A$505,R$2,'Détail fonctionnement'!$G$5:$G$505,"O",'Détail fonctionnement'!$B$5:$B$505,$A35) | S35: =Q35+R35 | T35: =SUMIFS('Détail fonctionnement'!$J$5:$J$505,'Détail fonctionnement'!$A$5:$A$505,T$2,'Détail fonctionnement'!$G$5:$G$505,"O",'Détail fonctionnement'!$B$5:$B$505,$A35) | U35: =S35+T35 | V35: =SUMIFS('Détail fonctionnement'!$J$5:$J$505,'Détail fonctionnement'!$A$5:$A$505,V$2,'Détail fonctionnement'!$G$5:$G$505,"O",'Détail fonctionnement'!$B$5:$B$505,$A35) | W35: =U35+V35
C36: SOCIETE GENERALE-IMMONEUF | D36: Dédié besoin de fonctionnement | F36: =M36/$E$3 | M36: ='Position CI 30-09'!F23
C37: ECOBANK-IMMONEUF | D37: Dédié besoin de fonctionnement | F37: =M37/$E$3 | M37: ='Position CI 30-09'!F24
C38: BACI - IMMONEUF | D38: Dédié besoin de fonctionnement | F38: =M38/$E$3 | M38: ='Position CI 30-09'!F25
A39: INFI SOFT | C39: INFI SOFT | F39: =M39/$E$3 | G39: =O39/$E$3 | H39: =Q39/$E$3 | I39: =S39/$E$3 | J39: =U39/$E$3 | K39: =W39/$E$3 | M39: =SUM(M40:M40) | N39: =SUMIFS('Détail fonctionnement'!$J$5:$J$505,'Détail fonctionnement'!$A$5:$A$505,N$2,'Détail fonctionnement'!$G$5:$G$505,"O",'Détail fonctionnement'!$B$5:$B$505,$A39) | O39: =M39+N39 | P39: =SUMIFS('Détail fonctionnement'!$J$5:$J$505,'Détail fonctionnement'!$A$5:$A$505,P$2,'Détail fonctionnement'!$G$5:$G$505,"O",'Détail fonctionnement'!$B$5:$B$505,$A39) | Q39: =O39+P39 | R39: =SUMIFS('Détail fonctionnement'!$J$5:$J$505,'Détail fonctionnement'!$A$5:$A$505,R$2,'Détail fonctionnement'!$G$5:$G$505,"O",'Détail fonctionnement'!$B$5:$B$505,$A39) | S39: =Q39+R39 | T39: =SUMIFS('Détail fonctionnement'!$J$5:$J$505,'Détail fonctionnement'!$A$5:$A$505,T$2,'Détail fonctionnement'!$G$5:$G$505,"O",'Détail fonctionnement'!$B$5:$B$505,$A39) | U39: =S39+T39 | V39: =SUMIFS('Détail fonctionnement'!$J$5:$J$505,'Détail fonctionnement'!$A$5:$A$505,V$2,'Détail fonctionnement'!$G$5:$G$505,"O",'Détail fonctionnement'!$B$5:$B$505,$A39) | W39: =U39+V39
C40: INFI SOFT - SIB | D40: Dédié besoin de fonctionnement | F40: =M40/$E$3 | M40: ='Position CI 30-09'!F26
A41: ODALYS CI | C41: ODALYS CI | F41: =M41/$E$3 | G41: =O41/$E$3 | H41: =Q41/$E$3 | I41: =S41/$E$3 | J41: =U41/$E$3 | K41: =W41/$E$3 | M41: =SUM(M42:M42) | N41: =SUMIFS('Détail fonctionnement'!$J$5:$J$505,'Détail fonctionnement'!$A$5:$A$505,N$2,'Détail fonctionnement'!$G$5:$G$505,"O",'Détail fonctionnement'!$B$5:$B$505,$A41) | O41: =M41+N41 | P41: =SUMIFS('Détail fonctionnement'!$J$5:$J$505,'Détail fonctionnement'!$A$5:$A$505,P$2,'Détail fonctionnement'!$G$5:$G$505,"O",'Détail fonctionnement'!$B$5:$B$505,$A41) | Q41: =O41+P41 | R41: =SUMIFS('Détail fonctionnement'!$J$5:$J$505,'Détail fonctionnement'!$A$5:$A$505,R$2,'Détail fonctionnement'!$G$5:$G$505,"O",'Détail fonctionnement'!$B$5:$B$505,$A41) | S41: =Q41+R41 | T41: =SUMIFS('Détail fonctionnement'!$J$5:$J$505,'Détail fonctionnement'!$A$5:$A$505,T$2,'Détail fonctionnement'!$G$5:$G$505,"O",'Détail fonctionnement'!$B$5:$B$505,$A41) | U41: =S41+T41 | V41: =SUMIFS('Détail fonctionnement'!$J$5:$J$505,'Détail fonctionnement'!$A$5:$A$505,V$2,'Détail fonctionnement'!$G$5:$G$505,"O",'Détail fonctionnement'!$B$5:$B$505,$A41) | W41: =U41+V41
C42: SOCIETE GENERALE-ODALYS | D42: Dédié besoin de fonctionnement | F42: =M42/$E$3 | M42: ='Position CI 30-09'!F27
...

Sheet Équilibrage S1
A1: Équilibrage et affectation des paiements – S1 (05/10 au 11/10/2026)
A2: Paiements : liens vers les feuilles de détail (S1, Retenu = O). Soldes : liens vers la position CI. Nivellements : tableau des virements ci-dessous (modifiable).
A4: Opérations à effectuer | B4: Paiement via | AB4: Observations
B5: TERASSON | E5: PICI | H5: SCI FIRST | J5: RIVIERA PARK | M5: SCO AO | R5: IMMONEUF | U5: FINAFRICA | W5: INFI | X5: ODALYS CI | Y5: AB CENTER | AA5: RHD CI
B6: BNI fonds projet | C6: SG | D6: ECO | E6: STB | F6: SG | G6: ECO | H6: STB | I6: SG | J6: BNI fonds projet | K6: BNI courant | L6: SG | M6: BACI Projet | N6: BACI courant | O6: BOA | P6: BACI AGORA | Q6: ECO | R6: SG | S6: BACI | T6: ECO | U6: SG | V6: ECO | W6: SIB | X6: SG | Y6: ECO | Z6: SG | AA6: payé par PICI
A7: NIVELLEMENT VIA PICI | B7: =SUMIFS($H$25:$H$55,$A$25:$A$55,"NIVELLEMENT VIA PICI",$E$25:$E$55,"TERASSON – BNI fonds projet")-SUMIFS($H$25:$H$55,$A$25:$A$55,"NIVELLEMENT VIA PICI",$C$25:$C$55,"TERASSON – BNI fonds projet") | C7: =SUMIFS($H$25:$H$55,$A$25:$A$55,"NIVELLEMENT VIA PICI",$E$25:$E$55,"TERASSON – SG")-SUMIFS($H$25:$H$55,$A$25:$A$55,"NIVELLEMENT VIA PICI",$C$25:$C$55,"TERASSON – SG") | D7: =SUMIFS($H$25:$H$55,$A$25:$A$55,"NIVELLEMENT VIA PICI",$E$25:$E$55,"TERASSON – ECO")-SUMIFS($H$25:$H$55,$A$25:$A$55,"NIVELLEMENT VIA PICI",$C$25:$C$55,"TERASSON – ECO") | E7: =SUMIFS($H$25:$H$55,$A$25:$A$55,"NIVELLEMENT VIA PICI",$E$25:$E$55,"PICI – STB")-SUMIFS($H$25:$H$55,$A$25:$A$55,"NIVELLEMENT VIA PICI",$C$25:$C$55,"PICI – STB") | F7: =SUMIFS($H$25:$H$55,$A$25:$A$55,"NIVELLEMENT VIA PICI",$E$25:$E$55,"PICI – SG")-SUMIFS($H$25:$H$55,$A$25:$A$55,"NIVELLEMENT VIA PICI",$C$25:$C$55,"PICI – SG") | G7: =SUMIFS($H$25:$H$55,$A$25:$A$55,"NIVELLEMENT VIA PICI",$E$25:$E$55,"PICI – ECO")-SUMIFS($H$25:$H$55,$A$25:$A$55,"NIVELLEMENT VIA PICI",$C$25:$C$55,"PICI – ECO") | H7: =SUMIFS($H$25:$H$55,$A$25:$A$55,"NIVELLEMENT VIA PICI",$E$25:$E$55,"SCI FIRST – STB")-SUMIFS($H$25:$H$55,$A$25:$A$55,"NIVELLEMENT VIA PICI",$C$25:$C$55,"SCI FIRST – STB") | I7: =SUMIFS($H$25:$H$55,$A$25:$A$55,"NIVELLEMENT VIA PICI",$E$25:$E$55,"SCI FIRST – SG")-SUMIFS($H$25:$H$55,$A$25:$A$55,"NIVELLEMENT VIA PICI",$C$25:$C$55,"SCI FIRST – SG") | J7: =SUMIFS($H$25:$H$55,$A$25:$A$55,"NIVELLEMENT VIA PICI",$E$25:$E$55,"RIVIERA PARK – BNI fonds projet")-SUMIFS($H$25:$H$55,$A$25:$A$55,"NIVELLEMENT VIA PICI",$C$25:$C$55,"RIVIERA PARK – BNI fonds projet") | K7: =SUMIFS($H$25:$H$55,$A$25:$A$55,"NIVELLEMENT VIA PICI",$E$25:$E$55,"RIVIERA PARK – BNI courant")-SUMIFS($H$25:$H$55,$A$25:$A$55,"NIVELLEMENT VIA PICI",$C$25:$C$55,"RIVIERA PARK – BNI courant") | L7: =SUMIFS($H$25:$H$55,$A$25:$A$55,"NIVELLEMENT VIA PICI",$E$25:$E$55,"RIVIERA PARK – SG")-SUMIFS($H$25:$H$55,$A$25:$A$55,"NIVELLEMENT VIA PICI",$C$25:$C$55,"RIVIERA PARK – SG") | M7: =SUMIFS($H$25:$H$55,$A$25:$A$55,"NIVELLEMENT VIA PICI",$E$25:$E$55,"SCO AO – BACI Projet")-SUMIFS($H$25:$H$55,$A$25:$A$55,"NIVELLEMENT VIA PICI",$C$25:$C$55,"SCO AO – BACI Projet") | N7: =SUMIFS($H$25:$H$55,$A$25:$A$55,"NIVELLEMENT VIA PICI",$E$25:$E$55,"SCO AO – BACI courant")-SUMIFS($H$25:$H$55,$A$25:$A$55,"NIVELLEMENT VIA PICI",$C$25:$C$55,"SCO AO – BACI courant") | O7: =SUMIFS($H$25:$H$55,$A$25:$A$55,"NIVELLEMENT VIA PICI",$E$25:$E$55,"SCO AO – BOA")-SUMIFS($H$25:$H$55,$A$25:$A$55,"NIVELLEMENT VIA PICI",$C$25:$C$55,"SCO AO – BOA") | P7: =SUMIFS($H$25:$H$55,$A$25:$A$55,"NIVELLEMENT VIA PICI",$E$25:$E$55,"SCO AO – BACI AGORA")-SUMIFS($H$25:$H$55,$A$25:$A$55,"NIVELLEMENT VIA PICI",$C$25:$C$55,"SCO AO – BACI AGORA") | Q7: =SUMIFS($H$25:$H$55,$A$25:$A$55,"NIVELLEMENT VIA PICI",$E$25:$E$55,"SCO AO – ECO")-SUMIFS($H$25:$H$55,$A$25:$A$55,"NIVELLEMENT VIA PICI",$C$25:$C$55,"SCO AO – ECO") | R7: =SUMIFS($H$25:$H$55,$A$25:$A$55,"NIVELLEMENT VIA PICI",$E$25:$E$55,"IMMONEUF – SG")-SUMIFS($H$25:$H$55,$A$25:$A$55,"NIVELLEMENT VIA PICI",$C$25:$C$55,"IMMONEUF – SG") | S7: =SUMIFS($H$25:$H$55,$A$25:$A$55,"NIVELLEMENT VIA PICI",$E$25:$E$55,"IMMONEUF – BACI")-SUMIFS($H$25:$H$55,$A$25:$A$55,"NIVELLEMENT VIA PICI",$C$25:$C$55,"IMMONEUF – BACI") | T7: =SUMIFS($H$25:$H$55,$A$25:$A$55,"NIVELLEMENT VIA PICI",$E$25:$E$55,"IMMONEUF – ECO")-SUMIFS($H$25:$H$55,$A$25:$A$55,"NIVELLEMENT VIA PICI",$C$25:$C$55,"IMMONEUF – ECO") | U7: =SUMIFS($H$25:$H$55,$A$25:$A$55,"NIVELLEMENT VIA PICI",$E$25:$E$55,"FINAFRICA – SG")-SUMIFS($H$25:$H$55,$A$25:$A$55,"NIVELLEMENT VIA PICI",$C$25:$C$55,"FINAFRICA – SG") | V7: =SUMIFS($H$25:$H$55,$A$25:$A$55,"NIVELLEMENT VIA PICI",$E$25:$E$55,"FINAFRICA – ECO")-SUMIFS($H$25:$H$55,$A$25:$A$55,"NIVELLEMENT VIA PICI",$C$25:$C$55,"FINAFRICA – ECO") | W7: =SUMIFS($H$25:$H$55,$A$25:$A$55,"NIVELLEMENT VIA PICI",$E$25:$E$55,"INFI – SIB")-SUMIFS($H$25:$H$55,$A$25:$A$55,"NIVELLEMENT VIA PICI",$C$25:$C$55,"INFI – SIB") | X7: =SUMIFS($H$25:$H$55,$A$25:$A$55,"NIVELLEMENT VIA PICI",$E$25:$E$55,"ODALYS CI – SG")-SUMIFS($H$25:$H$55,$A$25:$A$55,"NIVELLEMENT VIA PICI",$C$25:$C$55,"ODALYS CI – SG") | Y7: =SUMIFS($H$25:$H$55,$A$25:$A$55,"NIVELLEMENT VIA PICI",$E$25:$E$55,"AB CENTER – ECO")-SUMIFS($H$25:$H$55,$A$25:$A$55,"NIVELLEMENT VIA PICI",$C$25:$C$55,"AB CENTER – ECO") | Z7: =SUMIFS($H$25:$H$55,$A$25:$A$55,"NIVELLEMENT VIA PICI",$E$25:$E$55,"AB CENTER – SG")-SUMIFS($H$25:$H$55,$A$25:$A$55,"NIVELLEMENT VIA PICI",$C$25:$C$55,"AB CENTER – SG") | AA7: =SUMIFS($H$25:$H$55,$A$25:$A$55,"NIVELLEMENT VIA PICI",$E$25:$E$55,"RHD CI – payé par PICI")-SUMIFS($H$25:$H$55,$A$25:$A$55,"NIVELLEMENT VIA PICI",$C$25:$C$55,"RHD CI – payé par PICI") | AB7: Excédents PICI puis FIRST vers les sociétés en déficit : impôts, cotisations et salaires d'abord, fournisseurs ensuite
A8: AUTRES NIVELLEMENTS | B8: =SUMIFS($H$25:$H$55,$A$25:$A$55,"AUTRES NIVELLEMENTS",$E$25:$E$55,"TERASSON – BNI fonds projet")-SUMIFS($H$25:$H$55,$A$25:$A$55,"AUTRES NIVELLEMENTS",$C$25:$C$55,"TERASSON – BNI fonds projet") | C8: =SUMIFS($H$25:$H$55,$A$25:$A$55,"AUTRES NIVELLEMENTS",$E$25:$E$55,"TERASSON – SG")-SUMIFS($H$25:$H$55,$A$25:$A$55,"AUTRES NIVELLEMENTS",$C$25:$C$55,"TERASSON – SG") | D8: =SUMIFS($H$25:$H$55,$A$25:$A$55,"AUTRES NIVELLEMENTS",$E$25:$E$55,"TERASSON – ECO")-SUMIFS($H$25:$H$55,$A$25:$A$55,"AUTRES NIVELLEMENTS",$C$25:$C$55,"TERASSON – ECO") | E8: =SUMIFS($H$25:$H$55,$A$25:$A$55,"AUTRES NIVELLEMENTS",$E$25:$E$55,"PICI – STB")-SUMIFS($H$25:$H$55,$A$25:$A$55,"AUTRES NIVELLEMENTS",$C$25:$C$55,"PICI – STB") | F8: =SUMIFS($H$25:$H$55,$A$25:$A$55,"AUTRES NIVELLEMENTS",$E$25:$E$55,"PICI – SG")-SUMIFS($H$25:$H$55,$A$25:$A$55,"AUTRES NIVELLEMENTS",$C$25:$C$55,"PICI – SG") | G8: =SUMIFS($H$25:$H$55,$A$25:$A$55,"AUTRES NIVELLEMENTS",$E$25:$E$55,"PICI – ECO")-SUMIFS($H$25:$H$55,$A$25:$A$55,"AUTRES NIVELLEMENTS",$C$25:$C$55,"PICI – ECO") | H8: =SUMIFS($H$25:$H$55,$A$25:$A$55,"AUTRES NIVELLEMENTS",$E$25:$E$55,"SCI FIRST – STB")-SUMIFS($H$25:$H$55,$A$25:$A$55,"AUTRES NIVELLEMENTS",$C$25:$C$55,"SCI FIRST – STB") | I8: =SUMIFS($H$25:$H$55,$A$25:$A$55,"AUTRES NIVELLEMENTS",$E$25:$E$55,"SCI FIRST – SG")-SUMIFS($H$25:$H$55,$A$25:$A$55,"AUTRES NIVELLEMENTS",$C$25:$C$55,"SCI FIRST – SG") | J8: =SUMIFS($H$25:$H$55,$A$25:$A$55,"AUTRES NIVELLEMENTS",$E$25:$E$55,"RIVIERA PARK – BNI fonds projet")-SUMIFS($H$25:$H$55,$A$25:$A$55,"AUTRES NIVELLEMENTS",$C$25:$C$55,"RIVIERA PARK – BNI fonds projet") | K8: =SUMIFS($H$25:$H$55,$A$25:$A$55,"AUTRES NIVELLEMENTS",$E$25:$E$55,"RIVIERA PARK – BNI courant")-SUMIFS($H$25:$H$55,$A$25:$A$55,"AUTRES NIVELLEMENTS",$C$25:$C$55,"RIVIERA PARK – BNI courant") | L8: =SUMIFS($H$25:$H$55,$A$25:$A$55,"AUTRES NIVELLEMENTS",$E$25:$E$55,"RIVIERA PARK – SG")-SUMIFS($H$25:$H$55,$A$25:$A$55,"AUTRES NIVELLEMENTS",$C$25:$C$55,"RIVIERA PARK – SG") | M8: =SUMIFS($H$25:$H$55,$A$25:$A$55,"AUTRES NIVELLEMENTS",$E$25:$E$55,"SCO AO – BACI Projet")-SUMIFS($H$25:$H$55,$A$25:$A$55,"AUTRES NIVELLEMENTS",$C$25:$C$55,"SCO AO – BACI Projet") | N8: =SUMIFS($H$25:$H$55,$A$25:$A$55,"AUTRES NIVELLEMENTS",$E$25:$E$55,"SCO AO – BACI courant")-SUMIFS($H$25:$H$55,$A$25:$A$55,"AUTRES NIVELLEMENTS",$C$25:$C$55,"SCO AO – BACI courant") | O8: =SUMIFS($H$25:$H$55,$A$25:$A$55,"AUTRES NIVELLEMENTS",$E$25:$E$55,"SCO AO – BOA")-SUMIFS($H$25:$H$55,$A$25:$A$55,"AUTRES NIVELLEMENTS",$C$25:$C$55,"SCO AO – BOA") | P8: =SUMIFS($H$25:$H$55,$A$25:$A$55,"AUTRES NIVELLEMENTS",$E$25:$E$55,"SCO AO – BACI AGORA")-SUMIFS($H$25:$H$55,$A$25:$A$55,"AUTRES NIVELLEMENTS",$C$25:$C$55,"SCO AO – BACI AGORA") | Q8: =SUMIFS($H$25:$H$55,$A$25:$A$55,"AUTRES NIVELLEMENTS",$E$25:$E$55,"SCO AO – ECO")-SUMIFS($H$25:$H$55,$A$25:$A$55,"AUTRES NIVELLEMENTS",$C$25:$C$55,"SCO AO – ECO") | R8: =SUMIFS($H$25:$H$55,$A$25:$A$55,"AUTRES NIVELLEMENTS",$E$25:$E$55,"IMMONEUF – SG")-SUMIFS($H$25:$H$55,$A$25:$A$55,"AUTRES NIVELLEMENTS",$C$25:$C$55,"IMMONEUF – SG") | S8: =SUMIFS($H$25:$H$55,$A$25:$A$55,"AUTRES NIVELLEMENTS",$E$25:$E$55,"IMMONEUF – BACI")-SUMIFS($H$25:$H$55,$A$25:$A$55,"AUTRES NIVELLEMENTS",$C$25:$C$55,"IMMONEUF – BACI") | T8: =SUMIFS($H$25:$H$55,$A$25:$A$55,"AUTRES NIVELLEMENTS",$E$25:$E$55,"IMMONEUF – ECO")-SUMIFS($H$25:$H$55,$A$25:$A$55,"AUTRES NIVELLEMENTS",$C$25:$C$55,"IMMONEUF – ECO") | U8: =SUMIFS($H$25:$H$55,$A$25:$A$55,"AUTRES NIVELLEMENTS",$E$25:$E$55,"FINAFRICA – SG")-SUMIFS($H$25:$H$55,$A$25:$A$55,"AUTRES NIVELLEMENTS",$C$25:$C$55,"FINAFRICA – SG") | V8: =SUMIFS($H$25:$H$55,$A$25:$A$55,"AUTRES NIVELLEMENTS",$E$25:$E$55,"FINAFRICA – ECO")-SUMIFS($H$25:$H$55,$A$25:$A$55,"AUTRES NIVELLEMENTS",$C$25:$C$55,"FINAFRICA – ECO") | W8: =SUMIFS($H$25:$H$55,$A$25:$A$55,"AUTRES NIVELLEMENTS",$E$25:$E$55,"INFI – SIB")-SUMIFS($H$25:$H$55,$A$25:$A$55,"AUTRES NIVELLEMENTS",$C$25:$C$55,"INFI – SIB") | X8: =SUMIFS($H$25:$H$55,$A$25:$A$55,"AUTRES NIVELLEMENTS",$E$25:$E$55,"ODALYS CI – SG")-SUMIFS($H$25:$H$55,$A$25:$A$55,"AUTRES NIVELLEMENTS",$C$25:$C$55,"ODALYS CI – SG") | Y8: =SUMIFS($H$25:$H$55,$A$25:$A$55,"AUTRES NIVELLEMENTS",$E$25:$E$55,"AB CENTER – ECO")-SUMIFS($H$25:$H$55,$A$25:$A$55,"AUTRES NIVELLEMENTS",$C$25:$C$55,"AB CENTER – ECO") | Z8: =SUMIFS($H$25:$H$55,$A$25:$A$55,"AUTRES NIVELLEMENTS",$E$25:$E$55,"AB CENTER – SG")-SUMIFS($H$25:$H$55,$A$25:$A$55,"AUTRES NIVELLEMENTS",$C$25:$C$55,"AB CENTER – SG") | AA8: =SUMIFS($H$25:$H$55,$A$25:$A$55,"AUTRES NIVELLEMENTS",$E$25:$E$55,"RHD CI – payé par PICI")-SUMIFS($H$25:$H$55,$A$25:$A$55,"AUTRES NIVELLEMENTS",$C$25:$C$55,"RHD CI – payé par PICI") | AB8: Virements entre comptes d'une même entité (BNI-RIVIERA courant : sous réserve d'arbitrage)
A9: FOURNISSEURS-PROJETS | B9: =SUMIFS('Détail projets & dettes'!$M$5:$M$500,'Détail projets & dettes'!$A$5:$A$500,"S1",'Détail projets & dettes'!$B$5:$B$500,"TERASSON-PROJET",'Détail projets & dettes'!$J$5:$J$500,"O") | C9: =SUMIFS('Détail fonctionnement'!$J$5:$J$505,'Détail fonctionnement'!$A$5:$A$505,"S1",'Détail fonctionnement'!$B$5:$B$505,"TERASSON",'Détail fonctionnement'!$C$5:$C$505,"FOURNISSEURS - PROJET",'Détail fonctionnement'!$G$5:$G$505,"O") | E9: =SUMIFS('Détail fonctionnement'!$J$5:$J$505,'Détail fonctionnement'!$A$5:$A$505,"S1",'Détail fonctionnement'!$B$5:$B$505,"PICI",'Détail fonctionnement'!$C$5:$C$505,"FOURNISSEURS - PROJET",'Détail fonctionnement'!$G$5:$G$505,"O") | H9: =SUMIFS('Détail fonctionnement'!$J$5:$J$505,'Détail fonctionnement'!$A$5:$A$505,"S1",'Détail fonctionnement'!$B$5:$B$505,"FIRST",'Détail fonctionnement'!$C$5:$C$505,"FOURNISSEURS - PROJET",'Détail fonctionnement'!$G$5:$G$505,"O") | J9: =SUMIFS('Détail projets & dettes'!$M$5:$M$500,'Détail projets & dettes'!$A$5:$A$500,"S1",'Détail projets & dettes'!$B$5:$B$500,"RIVIERA-PROJET",'Détail projets & dettes'!$J$5:$J$500,"O") | L9: =SUMIFS('Détail fonctionnement'!$J$5:$J$505,'Détail fonctionnement'!$A$5:$A$505,"S1",'Détail fonctionnement'!$B$5:$B$505,"RIVIERA",'Détail fonctionnement'!$C$5:$C$505,"FOURNISSEURS - PROJET",'Détail fonctionnement'!$G$5:$G$505,"O") | M9: =SUMIFS('Détail fonctionnement'!$J$5:$J$505,'Détail fonctionnement'!$A$5:$A$505,"S1",'Détail fonctionnement'!$B$5:$B$505,"SCO AO",'Détail fonctionnement'!$C$5:$C$505,"FOURNISSEURS - PROJET",'Détail fonctionnement'!$G$5:$G$505,"O") | R9: =SUMIFS('Détail fonctionnement'!$J$5:$J$505,'Détail fonctionnement'!$A$5:$A$505,"S1",'Détail fonctionnement'!$B$5:$B$505,"IMMONEUF",'Détail fonctionnement'!$C$5:$C$505,"FOURNISSEURS - PROJET",'Détail fonctionnement'!$G$5:$G$505,"O") | U9: =SUMIFS('Détail fonctionnement'!$J$5:$J$505,'Détail fonctionnement'!$A$5:$A$505,"S1",'Détail fonctionnement'!$B$5:$B$505,"FINAFRICA",'Détail fonctionnement'!$C$5:$C$505,"FOURNISSEURS - PROJET",'Détail fonctionnement'!$G$5:$G$505,"O") | W9: =SUMIFS('Détail fonctionnement'!$J$5:$J$505,'Détail fonctionnement'!$A$5:$A$505,"S1",'Détail fonctionnement'!$B$5:$B$505,"INFI SOFT",'Détail fonctionnement'!$C$5:$C$505,"FOURNISSEURS - PROJET",'Détail fonctionnement'!$G$5:$G$505,"O") | X9: =SUMIFS('Détail fonctionnement'!$J$5:$J$505,'Détail fonctionnement'!$A$5:$A$505,"S1",'Détail fonctionnement'!$B$5:$B$505,"ODALYS CI",'Détail fonctionnement'!$C$5:$C$505,"FOURNISSEURS - PROJET",'Détail fonctionnement'!$G$5:$G$505,"O") | Y9: =SUMIFS('Détail fonctionnement'!$J$5:$J$505,'Détail fonctionnement'!$A$5:$A$505,"S1",'Détail fonctionnement'!$B$5:$B$505,"AB CENTER",'Détail fonctionnement'!$C$5:$C$505,"FOURNISSEURS - PROJET",'Détail fonctionnement'!$G$5:$G$505,"O") | AA9: =SUMIFS('Détail fonctionnement'!$J$5:$J$505,'Détail fonctionnement'!$A$5:$A$505,"S1",'Détail fonctionnement'!$B$5:$B$505,"RHD CI",'Détail fonctionnement'!$C$5:$C$505,"FOURNISSEURS - PROJET",'Détail fonctionnement'!$G$5:$G$505,"O") | AB9: Cash plans : comptes « Dédié paiement CPI » ; SCO AO : BACI-Projet
A10: FOURNISSEURS-FGX | C10: =SUMIFS('Détail fonctionnement'!$J$5:$J$505,'Détail fonctionnement'!$A$5:$A$505,"S1",'Détail fonctionnement'!$B$5:$B$505,"TERASSON",'Détail fonctionnement'!$C$5:$C$505,"FOURNISSEURS - FGX",'Détail fonctionnement'!$G$5:$G$505,"O") | E10: =SUMIFS('Détail fonctionnement'!$J$5:$J$505,'Détail fonctionnement'!$A$5:$A$505,"S1",'Détail fonctionnement'!$B$5:$B$505,"PICI",'Détail fonctionnement'!$C$5:$C$505,"FOURNISSEURS - FGX",'Détail fonctionnement'!$G$5:$G$505,"O") | H10: =SUMIFS('Détail fonctionnement'!$J$5:$J$505,'Détail fonctionnement'!$A$5:$A$505,"S1",'Détail fonctionnement'!$B$5:$B$505,"FIRST",'Détail fonctionnement'!$C$5:$C$505,"FOURNISSEURS - FGX",'Détail fonctionnement'!$G$5:$G$505,"O") | L10: =SUMIFS('Détail fonctionnement'!$J$5:$J$505,'Détail fonctionnement'!$A$5:$A$505,"S1",'Détail fonctionnement'!$B$5:$B$505,"RIVIERA",'Détail fonctionnement'!$C$5:$C$505,"FOURNISSEURS - FGX",'Détail fonctionnement'!$G$5:$G$505,"O") | N10: =SUMIFS('Détail fonctionnement'!$J$5:$J$505,'Détail fonctionnement'!$A$5:$A$505,"S1",'Détail fonctionnement'!$B$5:$B$505,"SCO AO",'Détail fonctionnement'!$C$5:$C$505,"FOURNISSEURS - FGX",'Détail fonctionnement'!$G$5:$G$505,"O") | R10: =SUMIFS('Détail fonctionnement'!$J$5:$J$505,'Détail fonctionnement'!$A$5:$A$505,"S1",'Détail fonctionnement'!$B$5:$B$505,"IMMONEUF",'Détail fonctionnement'!$C$5:$C$505,"FOURNISSEURS - FGX",'Détail fonctionnement'!$G$5:$G$505,"O") | U10: =SUMIFS('Détail fonctionnement'!$J$5:$J$505,'Détail fonctionnement'!$A$5:$A$505,"S1",'Détail fonctionnement'!$B$5:$B$505,"FINAFRICA",'Détail fonctionnement'!$C$5:$C$505,"FOURNISSEURS - FGX",'Détail fonctionnement'!$G$5:$G$505,"O") | W10: =SUMIFS('Détail fonctionnement'!$J$5:$J$505,'Détail fonctionnement'!$A$5:$A$505,"S1",'Détail fonctionnement'!$B$5:$B$505,"INFI SOFT",'Détail fonctionnement'!$C$5:$C$505,"FOURNISSEURS - FGX",'Détail fonctionnement'!$G$5:$G$505,"O") | X10: =SUMIFS('Détail fonctionnement'!$J$5:$J$505,'Détail fonctionnement'!$A$5:$A$505,"S1",'Détail fonctionnement'!$B$5:$B$505,"ODALYS CI",'Détail fonctionnement'!$C$5:$C$505,"FOURNISSEURS - FGX",'Détail fonctionnement'!$G$5:$G$505,"O") | Y10: =SUMIFS('Détail fonctionnement'!$J$5:$J$505,'Détail fonctionnement'!$A$5:$A$505,"S1",'Détail fonctionnement'!$B$5:$B$505,"AB CENTER",'Détail fonctionnement'!$C$5:$C$505,"FOURNISSEURS - FGX",'Détail fonctionnement'!$G$5:$G$505,"O") | AA10: =SUMIFS('Détail fonctionnement'!$J$5:$J$505,'Détail fonctionnement'!$A$5:$A$505,"S1",'Détail fonctionnement'!$B$5:$B$505,"RHD CI",'Détail fonctionnement'!$C$5:$C$505,"FOURNISSEURS - FGX",'Détail fonctionnement'!$G$5:$G$505,"O")
A11: IMPÔTS | C11: =SUMIFS('Détail fonctionnement'!$J$5:$J$505,'Détail fonctionnement'!$A$5:$A$505,"S1",'Détail fonctionnement'!$B$5:$B$505,"TERASSON",'Détail fonctionnement'!$C$5:$C$505,"IMPÔTS ET TAXES",'Détail fonctionnement'!$G$5:$G$505,"O") | E11: =SUMIFS('Détail fonctionnement'!$J$5:$J$505,'Détail fonctionnement'!$A$5:$A$505,"S1",'Détail fonctionnement'!$B$5:$B$505,"PICI",'Détail fonctionnement'!$C$5:$C$505,"IMPÔTS ET TAXES",'Détail fonctionnement'!$G$5:$G$505,"O") | H11: =SUMIFS('Détail fonctionnement'!$J$5:$J$505,'Détail fonctionnement'!$A$5:$A$505,"S1",'Détail fonctionnement'!$B$5:$B$505,"FIRST",'Détail fonctionnement'!$C$5:$C$505,"IMPÔTS ET TAXES",'Détail fonctionnement'!$G$5:$G$505,"O") | L11: =SUMIFS('Détail fonctionnement'!$J$5:$J$505,'Détail fonctionnement'!$A$5:$A$505,"S1",'Détail fonctionnement'!$B$5:$B$505,"RIVIERA",'Détail fonctionnement'!$C$5:$C$505,"IMPÔTS ET TAXES",'Détail fonctionnement'!$G$5:$G$505,"O") | N11: =SUMIFS('Détail fonctionnement'!$J$5:$J$505,'Détail fonctionnement'!$A$5:$A$505,"S1",'Détail fonctionnement'!$B$5:$B$505,"SCO AO",'Détail fonctionnement'!$C$5:$C$505,"IMPÔTS ET TAXES",'Détail fonctionnement'!$G$5:$G$505,"O") | R11: =SUMIFS('Détail fonctionnement'!$J$5:$J$505,'Détail fonctionnement'!$A$5:$A$505,"S1",'Détail fonctionnement'!$B$5:$B$505,"IMMONEUF",'Détail fonctionnement'!$C$5:$C$505,"IMPÔTS ET TAXES",'Détail fonctionnement'!$G$5:$G$505,"O") | U11: =SUMIFS('Détail fonctionnement'!$J$5:$J$505,'Détail fonctionnement'!$A$5:$A$505,"S1",'Détail fonctionnement'!$B$5:$B$505,"FINAFRICA",'Détail fonctionnement'!$C$5:$C$505,"IMPÔTS ET TAXES",'Détail fonctionnement'!$G$5:$G$505,"O") | W11: =SUMIFS('Détail fonctionnement'!$J$5:$J$505,'Détail fonctionnement'!$A$5:$A$505,"S1",'Détail fonctionnement'!$B$5:$B$505,"INFI SOFT",'Détail fonctionnement'!$C$5:$C$505,"IMPÔTS ET TAXES",'Détail fonctionnement'!$G$5:$G$505,"O") | X11: =SUMIFS('Détail fonctionnement'!$J$5:$J$505,'Détail fonctionnement'!$A$5:$A$505,"S1",'Détail fonctionnement'!$B$5:$B$505,"ODALYS CI",'Détail fonctionnement'!$C$5:$C$505,"IMPÔTS ET TAXES",'Détail fonctionnement'!$G$5:$G$505,"O") | Y11: =SUMIFS('Détail fonctionnement'!$J$5:$J$505,'Détail fonctionnement'!$A$5:$A$505,"S1",'Détail fonctionnement'!$B$5:$B$505,"AB CENTER",'Détail fonctionnement'!$C$5:$C$505,"IMPÔTS ET TAXES",'Détail fonctionnement'!$G$5:$G$505,"O") | AA11: =SUMIFS('Détail fonctionnement'!$J$5:$J$505,'Détail fonctionnement'!$A$5:$A$505,"S1",'Détail fonctionnement'!$B$5:$B$505,"RHD CI",'Détail fonctionnement'!$C$5:$C$505,"IMPÔTS ET TAXES",'Détail fonctionnement'!$G$5:$G$505,"O")
A12: CHARGES SOCIALES | C12: =SUMIFS('Détail fonctionnement'!$J$5:$J$505,'Détail fonctionnement'!$A$5:$A$505,"S1",'Détail fonctionnement'!$B$5:$B$505,"TERASSON",'Détail fonctionnement'!$C$5:$C$505,"CHARGES SOCIALES",'Détail fonctionnement'!$G$5:$G$505,"O") | E12: =SUMIFS('Détail fonctionnement'!$J$5:$J$505,'Détail fonctionnement'!$A$5:$A$505,"S1",'Détail fonctionnement'!$B$5:$B$505,"PICI",'Détail fonctionnement'!$C$5:$C$505,"CHARGES SOCIALES",'Détail fonctionnement'!$G$5:$G$505,"O") | H12: =SUMIFS('Détail fonctionnement'!$J$5:$J$505,'Détail fonctionnement'!$A$5:$A$505,"S1",'Détail fonctionnement'!$B$5:$B$505,"FIRST",'Détail fonctionnement'!$C$5:$C$505,"CHARGES SOCIALES",'Détail fonctionnement'!$G$5:$G$505,"O") | L12: =SUMIFS('Détail fonctionnement'!$J$5:$J$505,'Détail fonctionnement'!$A$5:$A$505,"S1",'Détail fonctionnement'!$B$5:$B$505,"RIVIERA",'Détail fonctionnement'!$C$5:$C$505,"CHARGES SOCIALES",'Détail fonctionnement'!$G$5:$G$505,"O") | N12: =SUMIFS('Détail fonctionnement'!$J$5:$J$505,'Détail fonctionnement'!$A$5:$A$505,"S1",'Détail fonctionnement'!$B$5:$B$505,"SCO AO",'Détail fonctionnement'!$C$5:$C$505,"CHARGES SOCIALES",'Détail fonctionnement'!$G$5:$G$505,"O") | R12: =SUMIFS('Détail fonctionnement'!$J$5:$J$505,'Détail fonctionnement'!$A$5:$A$505,"S1",'Détail fonctionnement'!$B$5:$B$505,"IMMONEUF",'Détail fonctionnement'!$C$5:$C$505,"CHARGES SOCIALES",'Détail fonctionnement'!$G$5:$G$505,"O") | U12: =SUMIFS('Détail fonctionnement'!$J$5:$J$505,'Détail fonctionnement'!$A$5:$A$505,"S1",'Détail fonctionnement'!$B$5:$B$505,"FINAFRICA",'Détail fonctionnement'!$C$5:$C$505,"CHARGES SOCIALES",'Détail fonctionnement'!$G$5:$G$505,"O") | W12: =SUMIFS('Détail fonctionnement'!$J$5:$J$505,'Détail fonctionnement'!$A$5:$A$505,"S1",'Détail fonctionnement'!$B$5:$B$505,"INFI SOFT",'Détail fonctionnement'!$C$5:$C$505,"CHARGES SOCIALES",'Détail fonctionnement'!$G$5:$G$505,"O") | X12: =SUMIFS('Détail fonctionnement'!$J$5:$J$505,'Détail fonctionnement'!$A$5:$A$505,"S1",'Détail fonctionnement'!$B$5:$B$505,"ODALYS CI",'Détail fonctionnement'!$C$5:$C$505,"CHARGES SOCIALES",'Détail fonctionnement'!$G$5:$G$505,"O") | Y12: =SUMIFS('Détail fonctionnement'!$J$5:$J$505,'Détail fonctionnement'!$A$5:$A$505,"S1",'Détail fonctionnement'!$B$5:$B$505,"AB CENTER",'Détail fonctionnement'!$C$5:$C$505,"CHARGES SOCIALES",'Détail fonctionnement'!$G$5:$G$505,"O") | AA12: =SUMIFS('Détail fonctionnement'!$J$5:$J$505,'Détail fonctionnement'!$A$5:$A$505,"S1",'Détail fonctionnement'!$B$5:$B$505,"RHD CI",'Détail fonctionnement'!$C$5:$C$505,"CHARGES SOCIALES",'Détail fonctionnement'!$G$5:$G$505,"O")
A13: SALAIRES | C13: =SUMIFS('Détail fonctionnement'!$J$5:$J$505,'Détail fonctionnement'!$A$5:$A$505,"S1",'Détail fonctionnement'!$B$5:$B$505,"TERASSON",'Détail fonctionnement'!$C$5:$C$505,"SALAIRES",'Détail fonctionnement'!$G$5:$G$505,"O") | E13: =SUMIFS('Détail fonctionnement'!$J$5:$J$505,'Détail fonctionnement'!$A$5:$A$505,"S1",'Détail fonctionnement'!$B$5:$B$505,"PICI",'Détail fonctionnement'!$C$5:$C$505,"SALAIRES",'Détail fonctionnement'!$G$5:$G$505,"O") | H13: =SUMIFS('Détail fonctionnement'!$J$5:$J$505,'Détail fonctionnement'!$A$5:$A$505,"S1",'Détail fonctionnement'!$B$5:$B$505,"FIRST",'Détail fonctionnement'!$C$5:$C$505,"SALAIRES",'Détail fonctionnement'!$G$5:$G$505,"O") | L13: =SUMIFS('Détail fonctionnement'!$J$5:$J$505,'Détail fonctionnement'!$A$5:$A$505,"S1",'Détail fonctionnement'!$B$5:$B$505,"RIVIERA",'Détail fonctionnement'!$C$5:$C$505,"SALAIRES",'Détail fonctionnement'!$G$5:$G$505,"O") | N13: =SUMIFS('Détail fonctionnement'!$J$5:$J$505,'Détail fonctionnement'!$A$5:$A$505,"S1",'Détail fonctionnement'!$B$5:$B$505,"SCO AO",'Détail fonctionnement'!$C$5:$C$505,"SALAIRES",'Détail fonctionnement'!$G$5:$G$505,"O") | R13: =SUMIFS('Détail fonctionnement'!$J$5:$J$505,'Détail fonctionnement'!$A$5:$A$505,"S1",'Détail fonctionnement'!$B$5:$B$505,"IMMONEUF",'Détail fonctionnement'!$C$5:$C$505,"SALAIRES",'Détail fonctionnement'!$G$5:$G$505,"O") | U13: =SUMIFS('Détail fonctionnement'!$J$5:$J$505,'Détail fonctionnement'!$A$5:$A$505,"S1",'Détail fonctionnement'!$B$5:$B$505,"FINAFRICA",'Détail fonctionnement'!$C$5:$C$505,"SALAIRES",'Détail fonctionnement'!$G$5:$G$505,"O") | W13: =SUMIFS('Détail fonctionnement'!$J$5:$J$505,'Détail fonctionnement'!$A$5:$A$505,"S1",'Détail fonctionnement'!$B$5:$B$505,"INFI SOFT",'Détail fonctionnement'!$C$5:$C$505,"SALAIRES",'Détail fonctionnement'!$G$5:$G$505,"O") | X13: =SUMIFS('Détail fonctionnement'!$J$5:$J$505,'Détail fonctionnement'!$A$5:$A$505,"S1",'Détail fonctionnement'!$B$5:$B$505,"ODALYS CI",'Détail fonctionnement'!$C$5:$C$505,"SALAIRES",'Détail fonctionnement'!$G$5:$G$505,"O") | Y13: =SUMIFS('Détail fonctionnement'!$J$5:$J$505,'Détail fonctionnement'!$A$5:$A$505,"S1",'Détail fonctionnement'!$B$5:$B$505,"AB CENTER",'Détail fonctionnement'!$C$5:$C$505,"SALAIRES",'Détail fonctionnement'!$G$5:$G$505,"O") | AA13: =SUMIFS('Détail fonctionnement'!$J$5:$J$505,'Détail fonctionnement'!$A$5:$A$505,"S1",'Détail fonctionnement'!$B$5:$B$505,"RHD CI",'Détail fonctionnement'!$C$5:$C$505,"SALAIRES",'Détail fonctionnement'!$G$5:$G$505,"O")
A14: ÉCHÉANCES | C14: =SUMIFS('Détail fonctionnement'!$J$5:$J$505,'Détail fonctionnement'!$A$5:$A$505,"S1",'Détail fonctionnement'!$B$5:$B$505,"TERASSON",'Détail fonctionnement'!$C$5:$C$505,"REMBOURSEMENT DE PRÊTS",'Détail fonctionnement'!$G$5:$G$505,"O") | E14: =SUMIFS('Détail fonctionnement'!$J$5:$J$505,'Détail fonctionnement'!$A$5:$A$505,"S1",'Détail fonctionnement'!$B$5:$B$505,"PICI",'Détail fonctionnement'!$C$5:$C$505,"REMBOURSEMENT DE PRÊTS",'Détail fonctionnement'!$G$5:$G$505,"O") | H14: =SUMIFS('Détail fonctionnement'!$J$5:$J$505,'Détail fonctionnement'!$A$5:$A$505,"S1",'Détail fonctionnement'!$B$5:$B$505,"FIRST",'Détail fonctionnement'!$C$5:$C$505,"REMBOURSEMENT DE PRÊTS",'Détail fonctionnement'!$G$5:$G$505,"O") | L14: =SUMIFS('Détail fonctionnement'!$J$5:$J$505,'Détail fonctionnement'!$A$5:$A$505,"S1",'Détail fonctionnement'!$B$5:$B$505,"RIVIERA",'Détail fonctionnement'!$C$5:$C$505,"REMBOURSEMENT DE PRÊTS",'Détail fonctionnement'!$G$5:$G$505,"O") | N14: =SUMIFS('Détail fonctionnement'!$J$5:$J$505,'Détail fonctionnement'!$A$5:$A$505,"S1",'Détail fonctionnement'!$B$5:$B$505,"SCO AO",'Détail fonctionnement'!$C$5:$C$505,"REMBOURSEMENT DE PRÊTS",'Détail fonctionnement'!$G$5:$G$505,"O") | R14: =SUMIFS('Détail fonctionnement'!$J$5:$J$505,'Détail fonctionnement'!$A$5:$A$505,"S1",'Détail fonctionnement'!$B$5:$B$505,"IMMONEUF",'Détail fonctionnement'!$C$5:$C$505,"REMBOURSEMENT DE PRÊTS",'Détail fonctionnement'!$G$5:$G$505,"O") | U14: =SUMIFS('Détail fonctionnement'!$J$5:$J$505,'Détail fonctionnement'!$A$5:$A$505,"S1",'Détail fonctionnement'!$B$5:$B$505,"FINAFRICA",'Détail fonctionnement'!$C$5:$C$505,"REMBOURSEMENT DE PRÊTS",'Détail fonctionnement'!$G$5:$G$505,"O") | W14: =SUMIFS('Détail fonctionnement'!$J$5:$J$505,'Détail fonctionnement'!$A$5:$A$505,"S1",'Détail fonctionnement'!$B$5:$B$505,"INFI SOFT",'Détail fonctionnement'!$C$5:$C$505,"REMBOURSEMENT DE PRÊTS",'Détail fonctionnement'!$G$5:$G$505,"O") | X14: =SUMIFS('Détail fonctionnement'!$J$5:$J$505,'Détail fonctionnement'!$A$5:$A$505,"S1",'Détail fonctionnement'!$B$5:$B$505,"ODALYS CI",'Détail fonctionnement'!$C$5:$C$505,"REMBOURSEMENT DE PRÊTS",'Détail fonctionnement'!$G$5:$G$505,"O") | Y14: =SUMIFS('Détail fonctionnement'!$J$5:$J$505,'Détail fonctionnement'!$A$5:$A$505,"S1",'Détail fonctionnement'!$B$5:$B$505,"AB CENTER",'Détail fonctionnement'!$C$5:$C$505,"REMBOURSEMENT DE PRÊTS",'Détail fonctionnement'!$G$5:$G$505,"O") | AA14: =SUMIFS('Détail fonctionnement'!$J$5:$J$505,'Détail fonctionnement'!$A$5:$A$505,"S1",'Détail fonctionnement'!$B$5:$B$505,"RHD CI",'Détail fonctionnement'!$C$5:$C$505,"REMBOURSEMENT DE PRÊTS",'Détail fonctionnement'!$G$5:$G$505,"O") | AB14: Échéances de prêts FIRST : dépenses de fonctionnement, compte payeur de FIRST
A15: AUTRES (ENCAISSEMENTS, DIVERS) | C15: =SUMIFS('Détail fonctionnement'!$J$5:$J$505,'Détail fonctionnement'!$A$5:$A$505,"S1",'Détail fonctionnement'!$B$5:$B$505,"TERASSON",'Détail fonctionnement'!$C$5:$C$505,"AUTRES DÉCAISSEMENTS",'Détail fonctionnement'!$G$5:$G$505,"O")+SUMIFS('Détail fonctionnement'!$J$5:$J$505,'Détail fonctionnement'!$A$5:$A$505,"S1",'Détail fonctionnement'!$B$5:$B$505,"TERASSON",'Détail fonctionnement'!$C$5:$C$505,"ENCAISSEMENTS",'Détail fonctionnement'!$G$5:$G$505,"O") | E15: =SUMIFS('Détail fonctionnement'!$J$5:$J$505,'Détail fonctionnement'!$A$5:$A$505,"S1",'Détail fonctionnement'!$B$5:$B$505,"PICI",'Détail fonctionnement'!$C$5:$C$505,"AUTRES DÉCAISSEMENTS",'Détail fonctionnement'!$G$5:$G$505,"O")+SUMIFS('Détail fonctionnement'!$J$5:$J$505,'Détail fonctionnement'!$A$5:$A$505,"S1",'Détail fonctionnement'!$B$5:$B$505,"PICI",'Détail fonctionnement'!$C$5:$C$505,"ENCAISSEMENTS",'Détail fonctionnement'!$G$5:$G$505,"O") | H15: =SUMIFS('Détail fonctionnement'!$J$5:$J$505,'Détail fonctionnement'!$A$5:$A$505,"S1",'Détail fonctionnement'!$B$5:$B$505,"FIRST",'Détail fonctionnement'!$C$5:$C$505,"AUTRES DÉCAISSEMENTS",'Détail fonctionnement'!$G$5:$G$505,"O")+SUMIFS('Détail fonctionnement'!$J$5:$J$505,'Détail fonctionnement'!$A$5:$A$505,"S1",'Détail fonctionnement'!$B$5:$B$505,"FIRST",'Détail fonctionnement'!$C$5:$C$505,"ENCAISSEMENTS",'Détail fonctionnement'!$G$5:$G$505,"O") | L15: =SUMIFS('Détail fonctionnement'!$J$5:$J$505,'Détail fonctionnement'!$A$5:$A$505,"S1",'Détail fonctionnement'!$B$5:$B$505,"RIVIERA",'Détail fonctionnement'!$C$5:$C$505,"AUTRES DÉCAISSEMENTS",'Détail fonctionnement'!$G$5:$G$505,"O")+SUMIFS('Détail fonctionnement'!$J$5:$J$505,'Détail fonctionnement'!$A$5:$A$505,"S1",'Détail fonctionnement'!$B$5:$B$505,"RIVIERA",'Détail fonctionnement'!$C$5:$C$505,"ENCAISSEMENTS",'Détail fonctionnement'!$G$5:$G$505,"O") | N15: =SUMIFS('Détail fonctionnement'!$J$5:$J$505,'Détail fonctionnement'!$A$5:$A$505,"S1",'Détail fonctionnement'!$B$5:$B$505,"SCO AO",'Détail fonctionnement'!$C$5:$C$505,"AUTRES DÉCAISSEMENTS",'Détail fonctionnement'!$G$5:$G$505,"O")+SUMIFS('Détail fonctionnement'!$J$5:$J$505,'Détail fonctionnement'!$A$5:$A$505,"S1",'Détail fonctionnement'!$B$5:$B$505,"SCO AO",'Détail fonctionnement'!$C$5:$C$505,"ENCAISSEMENTS",'Détail fonctionnement'!$G$5:$G$505,"O") | R15: =SUMIFS('Détail fonctionnement'!$J$5:$J$505,'Détail fonctionnement'!$A$5:$A$505,"S1",'Détail fonctionnement'!$B$5:$B$505,"IMMONEUF",'Détail fonctionnement'!$C$5:$C$505,"AUTRES DÉCAISSEMENTS",'Détail fonctionnement'!$G$5:$G$505,"O")+SUMIFS('Détail fonctionnement'!$J$5:$J$505,'Détail fonctionnement'!$A$5:$A$505,"S1",'Détail fonctionnement'!$B$5:$B$505,"IMMONEUF",'Détail fonctionnement'!$C$5:$C$505,"ENCAISSEMENTS",'Détail fonctionnement'!$G$5:$G$505,"O") | U15: =SUMIFS('Détail fonctionnement'!$J$5:$J$505,'Détail fonctionnement'!$A$5:$A$505,"S1",'Détail fonctionnement'!$B$5:$B$505,"FINAFRICA",'Détail fonctionnement'!$C$5:$C$505,"AUTRES DÉCAISSEMENTS",'Détail fonctionnement'!$G$5:$G$505,"O")+SUMIFS('Détail fonctionnement'!$J$5:$J$505,'Détail fonctionnement'!$A$5:$A$505,"S1",'Détail fonctionnement'!$B$5:$B$505,"FINAFRICA",'Détail fonctionnement'!$C$5:$C$505,"ENCAISSEMENTS",'Détail fonctionnement'!$G$5:$G$505,"O") | W15: =SUMIFS('Détail fonctionnement'!$J$5:$J$505,'Détail fonctionnement'!$A$5:$A$505,"S1",'Détail fonctionnement'!$B$5:$B$505,"INFI SOFT",'Détail fonctionnement'!$C$5:$C$505,"AUTRES DÉCAISSEMENTS",'Détail fonctionnement'!$G$5:$G$505,"O")+SUMIFS('Détail fonctionnement'!$J$5:$J$505,'Détail fonctionnement'!$A$5:$A$505,"S1",'Détail fonctionnement'!$B$5:$B$505,"INFI SOFT",'Détail fonctionnement'!$C$5:$C$505,"ENCAISSEMENTS",'Détail fonctionnement'!$G$5:$G$505,"O") | X15: =SUMIFS('Détail fonctionnement'!$J$5:$J$505,'Détail fonctionnement'!$A$5:$A$505,"S1",'Détail fonctionnement'!$B$5:$B$505,"ODALYS CI",'Détail fonctionnement'!$C$5:$C$505,"AUTRES DÉCAISSEMENTS",'Détail fonctionnement'!$G$5:$G$505,"O")+SUMIFS('Détail fonctionnement'!$J$5:$J$505,'Détail fonctionnement'!$A$5:$A$505,"S1",'Détail fonctionnement'!$B$5:$B$505,"ODALYS CI",'Détail fonctionnement'!$C$5:$C$505,"ENCAISSEMENTS",'Détail fonctionnement'!$G$5:$G$505,"O") | Y15: =SUMIFS('Détail fonctionnement'!$J$5:$J$505,'Détail fonctionnement'!$A$5:$A$505,"S1",'Détail fonctionnement'!$B$5:$B$505,"AB CENTER",'Détail fonctionnement'!$C$5:$C$505,"AUTRES DÉCAISSEMENTS",'Détail fonctionnement'!$G$5:$G$505,"O")+SUMIFS('Détail fonctionnement'!$J$5:$J$505,'Détail fonctionnement'!$A$5:$A$505,"S1",'Détail fonctionnement'!$B$5:$B$505,"AB CENTER",'Détail fonctionnement'!$C$5:$C$505,"ENCAISSEMENTS",'Détail fonctionnement'!$G$5:$G$505,"O") | AA15: =SUMIFS('Détail fonctionnement'!$J$5:$J$505,'Détail fonctionnement'!$A$5:$A$505,"S1",'Détail fonctionnement'!$B$5:$B$505,"RHD CI",'Détail fonctionnement'!$C$5:$C$505,"AUTRES DÉCAISSEMENTS",'Détail fonctionnement'!$G$5:$G$505,"O")+SUMIFS('Détail fonctionnement'!$J$5:$J$505,'Détail fonctionnement'!$A$5:$A$505,"S1",'Détail fonctionnement'!$B$5:$B$505,"RHD CI",'Détail fonctionnement'!$C$5:$C$505,"ENCAISSEMENTS",'Détail fonctionnement'!$G$5:$G$505,"O")
A16: ENREGISTREMENTS | C16: =SUMIFS('Détail fonctionnement'!$J$5:$J$505,'Détail fonctionnement'!$A$5:$A$505,"S1",'Détail fonctionnement'!$B$5:$B$505,"TERASSON",'Détail fonctionnement'!$C$5:$C$505,"ENREGISTREMENTS",'Détail fonctionnement'!$G$5:$G$505,"O") | E16: =SUMIFS('Détail fonctionnement'!$J$5:$J$505,'Détail fonctionnement'!$A$5:$A$505,"S1",'Détail fonctionnement'!$B$5:$B$505,"PICI",'Détail fonctionnement'!$C$5:$C$505,"ENREGISTREMENTS",'Détail fonctionnement'!$G$5:$G$505,"O") | H16: =SUMIFS('Détail fonctionnement'!$J$5:$J$505,'Détail fonctionnement'!$A$5:$A$505,"S1",'Détail fonctionnement'!$B$5:$B$505,"FIRST",'Détail fonctionnement'!$C$5:$C$505,"ENREGISTREMENTS",'Détail fonctionnement'!$G$5:$G$505,"O") | L16: =SUMIFS('Détail fonctionnement'!$J$5:$J$505,'Détail fonctionnement'!$A$5:$A$505,"S1",'Détail fonctionnement'!$B$5:$B$505,"RIVIERA",'Détail fonctionnement'!$C$5:$C$505,"ENREGISTREMENTS",'Détail fonctionnement'!$G$5:$G$505,"O") | N16: =SUMIFS('Détail fonctionnement'!$J$5:$J$505,'Détail fonctionnement'!$A$5:$A$505,"S1",'Détail fonctionnement'!$B$5:$B$505,"SCO AO",'Détail fonctionnement'!$C$5:$C$505,"ENREGISTREMENTS",'Détail fonctionnement'!$G$5:$G$505,"O") | R16: =SUMIFS('Détail fonctionnement'!$J$5:$J$505,'Détail fonctionnement'!$A$5:$A$505,"S1",'Détail fonctionnement'!$B$5:$B$505,"IMMONEUF",'Détail fonctionnement'!$C$5:$C$505,"ENREGISTREMENTS",'Détail fonctionnement'!$G$5:$G$505,"O") | U16: =SUMIFS('Détail fonctionnement'!$J$5:$J$505,'Détail fonctionnement'!$A$5:$A$505,"S1",'Détail fonctionnement'!$B$5:$B$505,"FINAFRICA",'Détail fonctionnement'!$C$5:$C$505,"ENREGISTREMENTS",'Détail fonctionnement'!$G$5:$G$505,"O") | W16: =SUMIFS('Détail fonctionnement'!$J$5:$J$505,'Détail fonctionnement'!$A$5:$A$505,"S1",'Détail fonctionnement'!$B$5:$B$505,"INFI SOFT",'Détail fonctionnement'!$C$5:$C$505,"ENREGISTREMENTS",'Détail fonctionnement'!$G$5:$G$505,"O") | X16: =SUMIFS('Détail fonctionnement'!$J$5:$J$505,'Détail fonctionnement'!$A$5:$A$505,"S1",'Détail fonctionnement'!$B$5:$B$505,"ODALYS CI",'Détail fonctionnement'!$C$5:$C$505,"ENREGISTREMENTS",'Détail fonctionnement'!$G$5:$G$505,"O") | Y16: =SUMIFS('Détail fonctionnement'!$J$5:$J$505,'Détail fonctionnement'!$A$5:$A$505,"S1",'Détail fonctionnement'!$B$5:$B$505,"AB CENTER",'Détail fonctionnement'!$C$5:$C$505,"ENREGISTREMENTS",'Détail fonctionnement'!$G$5:$G$505,"O") | AA16: =SUMIFS('Détail fonctionnement'!$J$5:$J$505,'Détail fonctionnement'!$A$5:$A$505,"S1",'Détail fonctionnement'!$B$5:$B$505,"RHD CI",'Détail fonctionnement'!$C$5:$C$505,"ENREGISTREMENTS",'Détail fonctionnement'!$G$5:$G$505,"O") | AB16: Hors besoin (droits d'enregistrement, Retenu = N)
A17: Total | B17: =SUM(B7:B16) | C17: =SUM(C7:C16) | D17: =SUM(D7:D16) | E17: =SUM(E7:E16) | F17: =SUM(F7:F16) | G17: =SUM(G7:G16) | H17: =SUM(H7:H16) | I17: =SUM(I7:I16) | ... AA17: =SUM(AA7:AA16)
A18: Solde au 30/09/2026 | B18: ='Position CI 30-09'!F29 | C18: ='Position CI 30-09'!F10 | D18: ='Position CI 30-09'!F11 | E18: ='Position CI 30-09'!F6 | F18: ='Position CI 30-09'!F5 | G18: ='Position CI 30-09'!F7 | H18: ='Position CI 30-09'!F9 | I18: ='Position CI 30-09'!F8 | J18: ='Position CI 30-09'!F28 | K18: ='Position CI 30-09'!F13 | L18: ='Position CI 30-09'!F12 | M18: ='Position CI 30-09'!F16 | N18: ='Position CI 30-09'!F15 | O18: ='Position CI 30-09'!F14 | P18: ='Position CI 30-09'!F17 | Q18: ='Position CI 30-09'!F18 | R18: ='Position CI 30-09'!F23 | S18: ='Position CI 30-09'!F25 | T18: ='Position CI 30-09'!F24 | U18: ='Position CI 30-09'!F19 | V18: ='Position CI 30-09'!F20 | W18: ='Position CI 30-09'!F26 | X18: ='Position CI 30-09'!F27 | Y18: ='Position CI 30-09'!F22 | Z18: ='Position CI 30-09'!F21 | AA18: 0
A19: Solde théorique fin S1 (11/10/2026) | B19: =B17+B18 | C19: =C17+C18 | D19: =D17+D18 | E19: =E17+E18 | F19: =F17+F18 | G19: =G17+G18 | H19: =H17+H18 | I19: =I17+I18 | ... AA19: =AA17+AA18
A20: Reste à financer (spot) ou à reporter | B20: =IF(B19<0,-B19,0) | C20: =IF(C19<0,-C19,0) | D20: =IF(D19<0,-D19,0) | E20: =IF(E19<0,-E19,0) | F20: =IF(F19<0,-F19,0) | G20: =IF(G19<0,-G19,0) | H20: =IF(H19<0,-H19,0) | I20: =IF(I19<0,-I19,0) | ... AA20: =IF(AA19<0,-AA19,0) | AB20: =SUM(B20:AA20)
A23: Virements à passer (modifiables : les nivellements et les soldes ci-dessus se recalculent)
A24: Type de nivellement | B24: N° | C24: Compte source | E24: Compte bénéficiaire | H24: Montant FCFA | I24: Motif
A25: AUTRES NIVELLEMENTS | B25: 1 | C25: RIVIERA PARK – BNI courant | E25: RIVIERA PARK – SG | H25: 500000000
E56: Total des virements | H56: =SUM(H25:H55)
A57: Comptes (liste de saisie)
A58: TERASSON – BNI fonds projet
A59: TERASSON – SG
A60: TERASSON – ECO
A61: PICI – STB
A62: PICI – SG
A63: PICI – ECO
A64: SCI FIRST – STB
A65: SCI FIRST – SG
A66: RIVIERA PARK – BNI fonds projet
A67: RIVIERA PARK – BNI courant
A68: RIVIERA PARK – SG
... A83: RHD CI – payé par PICI

Sheet Détail fonctionnement
A1: Détail des flux de fonctionnement (frais de structure) – FCFA
A2: Paiement effectué : saisir le montant payé en H (et sa date en I) ; seul le reste à payer (J) alimente le reporting. Paiement non prévu : ajouter une ligne en bas (semaine, entité, nature, libellé, montant négatif, Retenu = O).
A4: Semaine | B4: Entité | C4: Nature | D4: Fournisseur / libellé | E4: Montant FCFA | F4: Montant € | G4: Retenu (O/N) | H4: Payé FCFA (saisie) | I4: Date de paiement | J4: Reste à payer FCFA
A5: S1 | B5: PICI | C5: FOURNISSEURS - FGX | D5: BURMA | E5: -628015 | F5: =E5/'Reporting Hebdo'!$E$3 | G5: O | J5: =IF(E5<0,MIN(0,E5+N(H5)),MAX(0,E5-N(H5)))
A6: S1 | B6: PICI | C6: FOURNISSEURS - FGX | D6: CABINET JEAN-LUC RUELLE | E6: -5947200 | F6: =E6/'Reporting Hebdo'!$E$3 | G6: O | J6: =IF(E6<0,MIN(0,E6+N(H6)),MAX(0,E6-N(H6)))
A7: S1 | B7: PICI | C7: FOURNISSEURS - FGX | D7: CIE | E7: -50 | F7: =E7/'Reporting Hebdo'!$E$3 | G7: O | J7: =IF(E7<0,MIN(0,E7+N(H7)),MAX(0,E7-N(H7)))
A8: S1 | B8: PICI | C8: FOURNISSEURS - FGX | D8: DHL | E8: -157910 | F8: =E8/'Reporting Hebdo'!$E$3 | G8: O | J8: =IF(E8<0,MIN(0,E8+N(H8)),MAX(0,E8-N(H8)))
A9: S1 | B9: PICI | C9: FOURNISSEURS - FGX | D9: FOURNISSEURS DIVERS | E9: -7734197 | F9: =E9/'Reporting Hebdo'!$E$3 | G9: O | J9: =IF(E9<0,MIN(0,E9+N(H9)),MAX(0,E9-N(H9)))
A10: S1 | B10: PICI | C10: FOURNISSEURS - FGX | D10: HORUS TRAD SARL | E10: -324500 | F10: =E10/'Reporting Hebdo'!$E$3 | G10: O | J10: =IF(E10<0,MIN(0,E10+N(H10)),MAX(0,E10-N(H10)))
A11: S1 | B11: PICI | C11: FOURNISSEURS - FGX | D11: HORUS TRAD SARL | E11: -324500 | F11: =E11/'Reporting Hebdo'!$E$3 | G11: O | J11: =IF(E11<0,MIN(0,E11+N(H11)),MAX(0,E11-N(H11)))
A12: S1 | B12: PICI | C12: FOURNISSEURS - FGX | D12: IMPACT | E12: -5443898 | F12: =E12/'Reporting Hebdo'!$E$3 | G12: O | J12: =IF(E12<0,MIN(0,E12+N(H12)),MAX(0,E12-N(H12)))
A13: S1 | B13: PICI | C13: FOURNISSEURS - FGX | D13: JULIE BASSONVILLE | E13: -342735 | F13: =E13/'Reporting Hebdo'!$E$3 | G13: O | J13: =IF(E13<0,MIN(0,E13+N(H13)),MAX(0,E13-N(H13)))
A14: S1 | B14: PICI | C14: FOURNISSEURS - FGX | D14: LAVIVA | E14: -34002 | F14: =E14/'Reporting Hebdo'!$E$3 | G14: O | J14: =IF(E14<0,MIN(0,E14+N(H14)),MAX(0,E14-N(H14)))
A15: S1 | B15: PICI | C15: FOURNISSEURS - FGX | D15: LAVIVA | E15: -44002 | F15: =E15/'Reporting Hebdo'!$E$3 | G15: O | J15: =IF(E15<0,MIN(0,E15+N(H15)),MAX(0,E15-N(H15)))
A16: S1 | B16: PICI | C16: FOURNISSEURS - FGX | D16: LOXEA | E16: -7954048 | F16: =E16/'Reporting Hebdo'!$E$3 | G16: O | J16: =IF(E16<0,MIN(0,E16+N(H16)),MAX(0,E16-N(H16)))
... A204: S2 | B204: FIRST | C204: ENCAISSEMENTS | D204: Loyer octobre 2026 – SIEMENS ENERGY SARL | E204: 6113285 | F204: =E204/'Reporting Hebdo'!$E$3 | G204: N | J204: =IF(E204<0,MIN(0,E204+N(H204)),MAX(0,E204-N(H204)))
J205: =IF(E205<0,MIN(0,E205+N(H205)),MAX(0,E205-N(H205)))
J206: =IF(E206<0,MIN(0,E206+N(H206)),MAX(0,E206-N(H206)))
J207: =IF(E207<0,MIN(0,E207+N(H207)),MAX(0,E207-N(H207)))
J208: =IF(E208<0,MIN(0,E208+N(H208)),MAX(0,E208-N(H208)))
J209: =IF(E209<0,MIN(0,E209+N(H209)),MAX(0,E209-N(H209)))
J210: =IF(E210<0,MIN(0,E210+N(H210)),MAX(0,E210-N(H210)))
J211: =IF(E211<0,MIN(0,E211+N(H211)),MAX(0,E211-N(H211)))
J212: =IF(E212<0,MIN(0,E212+N(H212)),MAX(0,E212-N(H212)))
J213: =IF(E213<0,MIN(0,E213+N(H213)),MAX(0,E213-N(H213)))
J214: =IF(E214<0,MIN(0,E214+N(H214)),MAX(0,E214-N(H214)))
J215: =IF(E215<0,MIN(0,E215+N(H215)),MAX(0,E215-N(H215)))
J216: =IF(E216<0,MIN(0,E216+N(H216)),MAX(0,E216-N(H216)))
... J505: =IF(E505<0,MIN(0,E505+N(H505)),MAX(0,E505-N(H505)))

Sheet Détail projets & dettes
A1: Détail des flux projets & dettes (comptes dédiés)
A2: Paiement effectué : saisir le montant payé en FCFA en K (et sa date en L) ; seul le reste à payer (M) alimente le reporting.
A4: Semaine | B4: Compte dédié (clé) | C4: Entité | D4: Nature | E4: Code | F4: Libellé | G4: Entreprise | H4: Montant € HT | I4: Montant FCFA | J4: Retenu (O/N) | K4: Payé FCFA (saisie) | L4: Date de paiement | M4: Reste à payer FCFA
A5: S1 | B5: TERASSON-PROJET | C5: TERASSON | D5: Foncier | E5: FON 0009 | F5: Géomètre | G5: KOUAMELAN | H5: -5802 | I5: =H5*'Reporting Hebdo'!$E$3 | J5: O | M5: =IF(I5<0,MIN(0,I5+N(K5)),MAX(0,I5-N(K5)))
A6: S1 | B6: TERASSON-PROJET | C6: TERASSON | D6: Travaux | F6: 09 BGTB | H6: -86158.96 | I6: =H6*'Reporting Hebdo'!$E$3 | J6: O | M6: =IF(I6<0,MIN(0,I6+N(K6)),MAX(0,I6-N(K6)))
A7: S1 | B7: TERASSON-PROJET | C7: TERASSON | D7: Travaux | E7: BCC 0009 | F7: Autres travaux | H7: -12500 | I7: =H7*'Reporting Hebdo'!$E$3 | J7: O | M7: =IF(I7<0,MIN(0,I7+N(K7)),MAX(0,I7-N(K7)))
A8: S1 | B8: TERASSON-PROJET | C8: TERASSON | D8: Travaux | E8: BCC 0017 | F8: 02 GROS ŒUVRE & INSTALLATION DE CHANTIER | H8: -598630.99 | I8: =H8*'Reporting Hebdo'!$E$3 | J8: O | K8: 392676186 | L8: 07/10/2026 | M8: =IF(I8<0,MIN(0,I8+N(K8)),MAX(0,I8-N(K8)))
A9: S1 | B9: TERASSON-PROJET | C9: TERASSON | D9: Travaux | E9: BCC 0023 | F9: 07 SERRURERIE | H9: -164209.05 | I9: =H9*'Reporting Hebdo'!$E$3 | J9: O | M9: =IF(I9<0,MIN(0,I9+N(K9)),MAX(0,I9-N(K9)))
A10: S1 | B10: TERASSON-PROJET | C10: TERASSON | D10: Travaux | E10: BCC 0024 | F10: 08 CFO | H10: -224940.6 | I10: =H10*'Reporting Hebdo'!$E$3 | J10: O | M10: =IF(I10<0,MIN(0,I10+N(K10)),MAX(0,I10-N(K10)))
A11: S1 | B11: TERASSON-PROJET | C11: TERASSON | D11: Travaux | E11: BCC 0025 | F11: 09A CFA /SSI /GTB | H11: -338435.85 | I11: =H11*'Reporting Hebdo'!$E$3 | J11: O | M11: =IF(I11<0,MIN(0,I11+N(K11)),MAX(0,I11-N(K11)))
A12: S1 | B12: TERASSON-PROJET | C12: TERASSON | D12: Honoraires | E12: HON 0001 | F12: Architecte | G12: ARCHICONCEPT / MAP | H12: -54903 | I12: =H12*'Reporting Hebdo'!$E$3 | J12: O | M12: =IF(I12<0,MIN(0,I12+N(K12)),MAX(0,I12-N(K12)))
A13: S1 | B13: TERASSON-PROJET | C13: TERASSON | D13: Honoraires | E13: HON 0001 | F13: Architecte | G13: ARCHICONCEPT / MAP | H13: -6577 | I13: =H13*'Reporting Hebdo'!$E$3 | J13: O | M13: =IF(I13<0,MIN(0,I13+N(K13)),MAX(0,I13-N(K13)))
A14: S1 | B14: TERASSON-PROJET | C14: TERASSON | D14: Honoraires | E14: HON 0002 | F14: BET / MOE / SSI | G14: SCO | H14: -82323.18 | I14: =H14*'Reporting Hebdo'!$E$3 | J14: O | K14: 2709103 | L14: 07/10/2026 | M14: =IF(I14<0,MIN(0,I14+N(K14)),MAX(0,I14-N(K14)))
A15: S1 | B15: TERASSON-PROJET | C15: TERASSON | D15: Honoraires | E15: HON 0005 | F15: Bureau de contrôle | G15: BUREAU VERITAS | H15: -8415.19 | I15: =H15*'Reporting Hebdo'!$E$3 | J15: O | M15: =IF(I15<0,MIN(0,I15+N(K15)),MAX(0,I15-N(K15)))
A16: S1 | B16: TERASSON-PROJET | C16: TERASSON | D16: Honoraires | E16: HON 0006 | F16: CSPS | G16: SOCOTEC | H16: -6738.37 | I16: =H16*'Reporting Hebdo'!$E$3 | J16: O | M16: =IF(I16<0,MIN(0,I16+N(K16)),MAX(0,I16-N(K16)))
A17: S1 | B17: TERASSON-PROJET | C17: TERASSON | D17: Honoraires | E17: HON 0007 | F17: E&S | G17: ANDE / ENVAL / INSUCO / BIOTOPE / IVOIRE HYDROGENE | H17: -105395.81 | I17: =H17*'Reporting Hebdo'!$E$3 | J17: O | M17: =IF(I17<0,MIN(0,I17+N(K17)),MAX(0,I17-N(K17)))
A18: S1 | B18: TERASSON-PROJET | C18: TERASSON | D18: Honoraires | E18: HON 0009 | F18: Divers honoraires | G18: PROJEX / DIPHONE / LUSEO / BET GAURY | H18: -7000 | I18: =H18*'Reporting Hebdo'!$E$3 | J18: O | M18: =IF(I18<0,MIN(0,I18+N(K18)),MAX(0,I18-N(K18)))
A19: S1 | B19: TERASSON-PROJET | C19: TERASSON | D19: Honoraires | E19: HON 0010 | F19: Retenue à la source (prestataires étrangers) | H19: -48527.84 | I19: =H19*'Reporting Hebdo'!$E$3 | J19: O | M19: =IF(I19<0,MIN(0,I19+N(K19)),MAX(0,I19-N(K19)))
A20: S1 | B20: TERASSON-PROJET | C20: TERASSON | D20: Autres dépenses | E20: AUD 0007 | F20: Frais Divers | G20: YABA & KUMBA / SINTALI / VOLTERE | H20: -10000 | I20: =H20*'Reporting Hebdo'!$E$3 | J20: O | M20: =IF(I20<0,MIN(0,I20+N(K20)),MAX(0,I20-N(K20)))
A21: S1 | B21: TERASSON-PROJET | C21: TERASSON | D21: Autres dépenses | E21: AUD 0012 | F21: Autres frais financiers (Frais de Due Diligence) | G21: DWF/IFC | H21: -1255555.2 | I21: =H21*'Reporting Hebdo'!$E$3 | J21: O | M21: =IF(I21<0,MIN(0,I21+N(K21)),MAX(0,I21-N(K21)))
A22: S1 | B22: TERASSON-PROJET | C22: TERASSON | D22: Frais financiers | E22: FFI 0001 | F22: Intérêts sur compte courant | H22: -128661.33 | I22: =H22*'Reporting Hebdo'!$E$3 | J22: O | M22: =IF(I22<0,MIN(0,I22+N(K22)),MAX(0,I22-N(K22)))
A23: S1 | B23: TERASSON-PROJET | C23: TERASSON | D23: Frais financiers | E23: FFI 0005 | F23: Frais Financiers Coupons Invest | H23: -212269.89 | I23: =H23*'Reporting Hebdo'!$E$3 | J23: O | M23: =IF(I23<0,MIN(0,I23+N(K23)),MAX(0,I23-N(K23)))
A24: S1 | B24: RIVIERA-PROJET | C24: RIVIERA | D24: Foncier | E24: FON 0009 | F24: Géomètre | G24: ATELIER TOPOGRAPHIQUE KOTOKOU / CYGE / SG2T | H24: -2000 | I24: =H24*'Reporting Hebdo'!$E$3 | J24: O | M24: =IF(I24<0,MIN(0,I24+N(K24)),MAX(0,I24-N(K24)))
